<?xml version="1.0" encoding="utf-8"?>
<!-- This URDF was automatically created by SolidWorks to URDF Exporter! Originally created by Stephen Brawner (brawner@gmail.com) 
     Commit Version: 1.6.0-4-g7f85cfe  Build Version: 1.6.7995.38578
     For more information, please see http://wiki.ros.org/sw_urdf_exporter -->
<robot
  name="urdf_export_5">
  <link
    name="base_link">
    <inertial>
      <origin
        xyz="3.1294322702377E-05 -0.00258891220487617 0.00393729675276078"
        rpy="0 0 0" />
      <mass
        value="15.9199897349552" />
      <inertia
        ixx="0.16029657050812"
        ixy="9.30125647896142E-08"
        ixz="-1.151739720202E-07"
        iyy="0.10450825447933"
        iyz="3.34278528004388E-05"
        izz="0.256578303508712" />
    </inertial>
    <visual>
      <origin
        xyz="0 0 0"
        rpy="0 0 0" />
      <geometry>
        <mesh
          filename="package://urdf_export_5/meshes/base_link.STL" />
      </geometry>
      <material
        name="">
        <color
          rgba="0.898039215686275 0.917647058823529 0.929411764705882 1" />
      </material>
    </visual>
    <collision>
      <origin
        xyz="0 0 0"
        rpy="0 0 0" />
      <geometry>
        <mesh
          filename="package://urdf_export_5/meshes/base_link.STL" />
      </geometry>
    </collision>
  </link>
  <link
    name="thruster0">
    <inertial>
      <origin
        xyz="0.323784730482404 0.276256318506649 -0.017377648049658"
        rpy="0 0 0" />
      <mass
        value="0.00774021849814979" />
      <inertia
        ixx="2.20791766768821E-06"
        ixy="5.62380378325671E-10"
        ixz="2.16577287098631E-12"
        iyy="2.20652839106572E-06"
        iyz="-2.45687100891391E-11"
        izz="3.21487517336415E-06" />
    </inertial>
    <visual>
      <origin
        xyz="0 0 0"
        rpy="0 0 0" />
      <geometry>
        <mesh
          filename="package://urdf_export_5/meshes/thruster0.STL" />
      </geometry>
      <material
        name="">
        <color
          rgba="0.792156862745098 0.819607843137255 0.933333333333333 1" />
      </material>
    </visual>
    <collision>
      <origin
        xyz="0 0 0"
        rpy="0 0 0" />
      <geometry>
        <mesh
          filename="package://urdf_export_5/meshes/thruster0.STL" />
      </geometry>
    </collision>
  </link>
  <joint
    name="thruster_joint_0"
    type="revolute">
    <origin
      xyz="0 0 0"
      rpy="0 0 0" />
    <parent
      link="base_link" />
    <child
      link="thruster0" />
    <axis
      xyz="0 0 -1" />
    <limit
      lower="-1000000000000"
      upper="1000000000000"
      effort="-1"
      velocity="-1" />
  </joint>
  <link
    name="thruster_4">
    <inertial>
      <origin
        xyz="0.234155373512138 0.217389022125226 0.00437645514218995"
        rpy="0 0 0" />
      <mass
        value="0.00774122350372358" />
      <inertia
        ixx="2.71107411778506E-06"
        ixy="-5.04161341958956E-07"
        ixz="3.47772393895922E-10"
        iyy="2.71120408706306E-06"
        iyz="3.21975756693258E-10"
        izz="2.20793678637294E-06" />
    </inertial>
    <visual>
      <origin
        xyz="0 0 0"
        rpy="0 0 0" />
      <geometry>
        <mesh
          filename="package://urdf_export_5/meshes/thruster_4.STL" />
      </geometry>
      <material
        name="">
        <color
          rgba="0.792156862745098 0.819607843137255 0.933333333333333 1" />
      </material>
    </visual>
    <collision>
      <origin
        xyz="0 0 0"
        rpy="0 0 0" />
      <geometry>
        <mesh
          filename="package://urdf_export_5/meshes/thruster_4.STL" />
      </geometry>
    </collision>
  </link>
  <joint
    name="thruster_joint_4"
    type="revolute">
    <origin
      xyz="0 0 0"
      rpy="0 0 0" />
    <parent
      link="base_link" />
    <child
      link="thruster_4" />
    <axis
      xyz="-0.707106781186552 0.707106781186543 0" />
    <limit
      lower="-1000000000000"
      upper="1000000000000"
      effort="-1"
      velocity="-1" />
  </joint>
  <link
    name="thruster5">
    <inertial>
      <origin
        xyz="0.234157627548012 -0.229457746677766 0.00437406175427406"
        rpy="0 0 0" />
      <mass
        value="0.00774117302951113" />
      <inertia
        ixx="2.71149453962259E-06"
        ixy="5.03800485554769E-07"
        ixz="5.48170586533239E-10"
        iyy="2.71144529613185E-06"
        iyz="-5.5746044883274E-10"
        izz="2.20720962504507E-06" />
    </inertial>
    <visual>
      <origin
        xyz="0 0 0"
        rpy="0 0 0" />
      <geometry>
        <mesh
          filename="package://urdf_export_5/meshes/thruster5.STL" />
      </geometry>
      <material
        name="">
        <color
          rgba="0.792156862745098 0.819607843137255 0.933333333333333 1" />
      </material>
    </visual>
    <collision>
      <origin
        xyz="0 0 0"
        rpy="0 0 0" />
      <geometry>
        <mesh
          filename="package://urdf_export_5/meshes/thruster5.STL" />
      </geometry>
    </collision>
  </link>
  <joint
    name="thruster_joint_5"
    type="revolute">
    <origin
      xyz="0 0 0"
      rpy="0 0 0" />
    <parent
      link="base_link" />
    <child
      link="thruster5" />
    <axis
      xyz="-0.707106781186544 -0.707106781186551 0" />
    <limit
      lower="-1000000000000"
      upper="1000000000000"
      effort="-1"
      velocity="-1" />
  </joint>
  <link
    name="thruster6">
    <inertial>
      <origin
        xyz="-0.234092984343292 -0.229456600348887 0.00437741205399081"
        rpy="0 0 0" />
      <mass
        value="0.00774208667120787" />
      <inertia
        ixx="2.7116145591577E-06"
        ixy="-5.04278878343059E-07"
        ixz="-5.32978321791195E-10"
        iyy="2.71159769781301E-06"
        iyz="-4.40645678582531E-10"
        izz="2.20821716534477E-06" />
    </inertial>
    <visual>
      <origin
        xyz="0 0 0"
        rpy="0 0 0" />
      <geometry>
        <mesh
          filename="package://urdf_export_5/meshes/thruster6.STL" />
      </geometry>
      <material
        name="">
        <color
          rgba="0.792156862745098 0.819607843137255 0.933333333333333 1" />
      </material>
    </visual>
    <collision>
      <origin
        xyz="0 0 0"
        rpy="0 0 0" />
      <geometry>
        <mesh
          filename="package://urdf_export_5/meshes/thruster6.STL" />
      </geometry>
    </collision>
  </link>
  <joint
    name="thruster_joint_6"
    type="continuous">
    <origin
      xyz="0 0 0"
      rpy="0 0 0" />
    <parent
      link="base_link" />
    <child
      link="thruster6" />
    <axis
      xyz="0.707106781186551 -0.707106781186544 0" />
    <limit
      lower="-1000000000000"
      upper="1000000000000"
      effort="-1"
      velocity="-1" />
  </joint>
  <link
    name="thruster1">
    <inertial>
      <origin
        xyz="0.323785319876402 -0.288321051890773 -0.017377450240959"
        rpy="0 0 0" />
      <mass
        value="0.00773999910275849" />
      <inertia
        ixx="2.20644758396638E-06"
        ixy="9.80149056457269E-11"
        ixz="-1.65242619966251E-11"
        iyy="2.20797186512427E-06"
        iyz="-7.19290629496094E-12"
        izz="3.21483198556822E-06" />
    </inertial>
    <visual>
      <origin
        xyz="0 0 0"
        rpy="0 0 0" />
      <geometry>
        <mesh
          filename="package://urdf_export_5/meshes/thruster1.STL" />
      </geometry>
      <material
        name="">
        <color
          rgba="0.792156862745098 0.819607843137255 0.933333333333333 1" />
      </material>
    </visual>
    <collision>
      <origin
        xyz="0 0 0"
        rpy="0 0 0" />
      <geometry>
        <mesh
          filename="package://urdf_export_5/meshes/thruster1.STL" />
      </geometry>
    </collision>
  </link>
  <joint
    name="thruster_joint_1"
    type="revolute">
    <origin
      xyz="0 0 0"
      rpy="0 0 0" />
    <parent
      link="base_link" />
    <child
      link="thruster1" />
    <axis
      xyz="0 0 -1" />
    <limit
      lower="-1000000000000"
      upper="1000000000000"
      effort="-1"
      velocity="-1" />
  </joint>
  <link
    name="thruster7">
    <inertial>
      <origin
        xyz="-0.234091044934303 0.217389360781946 0.00437544851520705"
        rpy="0 0 0" />
      <mass
        value="0.00774152572047315" />
      <inertia
        ixx="2.71170960756965E-06"
        ixy="5.03685533391387E-07"
        ixz="-2.76374605222853E-10"
        iyy="2.7117423364615E-06"
        iyz="2.26652392888866E-10"
        izz="2.20699309720568E-06" />
    </inertial>
    <visual>
      <origin
        xyz="0 0 0"
        rpy="0 0 0" />
      <geometry>
        <mesh
          filename="package://urdf_export_5/meshes/thruster7.STL" />
      </geometry>
      <material
        name="">
        <color
          rgba="0.792156862745098 0.819607843137255 0.933333333333333 1" />
      </material>
    </visual>
    <collision>
      <origin
        xyz="0 0 0"
        rpy="0 0 0" />
      <geometry>
        <mesh
          filename="package://urdf_export_5/meshes/thruster7.STL" />
      </geometry>
    </collision>
  </link>
  <joint
    name="thruster_joint_7"
    type="revolute">
    <origin
      xyz="0 0 0"
      rpy="0 0 0" />
    <parent
      link="base_link" />
    <child
      link="thruster7" />
    <axis
      xyz="0.707106781186544 0.707106781186551 0" />
    <limit
      lower="-1000000000000"
      upper="1000000000000"
      effort="-1"
      velocity="-1" />
  </joint>
  <link
    name="thruster2">
    <inertial>
      <origin
        xyz="-0.323718736400264 -0.288321051890773 -0.0173774502409574"
        rpy="0 0 0" />
      <mass
        value="0.00773999910275899" />
      <inertia
        ixx="2.20644758396669E-06"
        ixy="9.80149055464329E-11"
        ixz="-1.65242619625039E-11"
        iyy="2.20797186512433E-06"
        iyz="-7.19290634992644E-12"
        izz="3.21483198556861E-06" />
    </inertial>
    <visual>
      <origin
        xyz="0 0 0"
        rpy="0 0 0" />
      <geometry>
        <mesh
          filename="package://urdf_export_5/meshes/thruster2.STL" />
      </geometry>
      <material
        name="">
        <color
          rgba="0.792156862745098 0.819607843137255 0.933333333333333 1" />
      </material>
    </visual>
    <collision>
      <origin
        xyz="0 0 0"
        rpy="0 0 0" />
      <geometry>
        <mesh
          filename="package://urdf_export_5/meshes/thruster2.STL" />
      </geometry>
    </collision>
  </link>
  <joint
    name="thruster_joint_2"
    type="revolute">
    <origin
      xyz="0 0 0"
      rpy="0 0 0" />
    <parent
      link="base_link" />
    <child
      link="thruster2" />
    <axis
      xyz="0 0 -1" />
    <limit
      lower="-1000000000000"
      upper="1000000000000"
      effort="-1"
      velocity="-1" />
  </joint>
  <link
    name="thruster3">
    <inertial>
      <origin
        xyz="-0.32371873867231 0.27625447477941 -0.0173774499441444"
        rpy="0 0 0" />
      <mass
        value="0.00773999839485365" />
      <inertia
        ixx="2.20644757938028E-06"
        ixy="9.74818949513116E-11"
        ixz="-1.65665882909667E-11"
        iyy="2.20797120661068E-06"
        iyz="-7.34282301706901E-12"
        izz="3.21483134700435E-06" />
    </inertial>
    <visual>
      <origin
        xyz="0 0 0"
        rpy="0 0 0" />
      <geometry>
        <mesh
          filename="package://urdf_export_5/meshes/thruster3.STL" />
      </geometry>
      <material
        name="">
        <color
          rgba="0.792156862745098 0.819607843137255 0.933333333333333 1" />
      </material>
    </visual>
    <collision>
      <origin
        xyz="0 0 0"
        rpy="0 0 0" />
      <geometry>
        <mesh
          filename="package://urdf_export_5/meshes/thruster3.STL" />
      </geometry>
    </collision>
  </link>
  <joint
    name="thruster_joint_3"
    type="revolute">
    <origin
      xyz="0 0 0"
      rpy="0 0 0" />
    <parent
      link="base_link" />
    <child
      link="thruster3" />
    <axis
      xyz="0 0 -1" />
    <limit
      lower="-1000000000000"
      upper="1000000000000"
      effort="-1"
      velocity="-1" />
  </joint>
  <link
    name="camera_zed">
    <inertial>
      <origin
        xyz="2.77038521082847E-06 0.182851326507769 0.0137084897151045"
        rpy="0 0 0" />
      <mass
        value="0.152258681193596" />
      <inertia
        ixx="2.28175456045055E-05"
        ixy="-2.40028104906173E-09"
        ixz="-6.22430178494732E-09"
        iyy="0.000372325024159044"
        iyz="-3.15958302329698E-08"
        izz="0.000374742680432966" />
    </inertial>
    <visual>
      <origin
        xyz="0 0 0"
        rpy="0 0 0" />
      <geometry>
        <mesh
          filename="package://urdf_export_5/meshes/camera_zed.STL" />
      </geometry>
      <material
        name="">
        <color
          rgba="0.627450980392157 0.627450980392157 0.627450980392157 1" />
      </material>
    </visual>
    <collision>
      <origin
        xyz="0 0 0"
        rpy="0 0 0" />
      <geometry>
        <mesh
          filename="package://urdf_export_5/meshes/camera_zed.STL" />
      </geometry>
    </collision>
  </link>
  <joint
    name="camera_zed_joint"
    type="fixed">
    <origin
      xyz="0 0 0"
      rpy="0 0 0" />
    <parent
      link="base_link" />
    <child
      link="camera_zed" />
    <axis
      xyz="0 0 0" />
    <limit
      lower="0"
      upper="0"
      effort="0"
      velocity="0" />
  </joint>
  <link
    name="dvl_a50">
    <inertial>
      <origin
        xyz="4.99301509441633E-07 0.00281117625181808 -0.0536543503907734"
        rpy="0 0 0" />
      <mass
        value="0.25633622835366" />
      <inertia
        ixx="0.000223787635688703"
        ixy="-3.67946224935447E-10"
        ixz="-6.46401067920919E-10"
        iyy="0.000219098774432553"
        iyz="-4.23615732189484E-08"
        izz="0.000418276343910706" />
    </inertial>
    <visual>
      <origin
        xyz="0 0 0"
        rpy="0 0 0" />
      <geometry>
        <mesh
          filename="package://urdf_export_5/meshes/dvl_a50.STL" />
      </geometry>
      <material
        name="">
        <color
          rgba="0.792156862745098 0.819607843137255 0.933333333333333 1" />
      </material>
    </visual>
    <collision>
      <origin
        xyz="0 0 0"
        rpy="0 0 0" />
      <geometry>
        <mesh
          filename="package://urdf_export_5/meshes/dvl_a50.STL" />
      </geometry>
    </collision>
  </link>
  <joint
    name="dvl_joint"
    type="fixed">
    <origin
      xyz="0 0 0"
      rpy="0 0 0" />
    <parent
      link="base_link" />
    <child
      link="dvl_a50" />
    <axis
      xyz="0 0 0" />
  </joint>
  <link
    name="imu_targetpoint0">
    <inertial>
      <origin
        xyz="0.025536388038816 -0.0205462531681684 0.0463231699704986"
        rpy="0 0 0" />
      <mass
        value="0.00550725674074068" />
      <inertia
        ixx="5.70520825882089E-07"
        ixy="-9.49293716940102E-09"
        ixz="-5.681763099075E-10"
        iyy="6.25529402959275E-07"
        iyz="4.94930664045547E-10"
        izz="1.15056899729882E-06" />
    </inertial>
    <visual>
      <origin
        xyz="0 0 0"
        rpy="0 0 0" />
      <geometry>
        <mesh
          filename="package://urdf_export_5/meshes/imu_targetpoint0.STL" />
      </geometry>
      <material
        name="">
        <color
          rgba="0.792156862745098 0.819607843137255 0.933333333333333 1" />
      </material>
    </visual>
    <collision>
      <origin
        xyz="0 0 0"
        rpy="0 0 0" />
      <geometry>
        <mesh
          filename="package://urdf_export_5/meshes/imu_targetpoint0.STL" />
      </geometry>
    </collision>
  </link>
  <joint
    name="imu_targetpoint0_joint"
    type="fixed">
    <origin
      xyz="0 0 0"
      rpy="0 0 0" />
    <parent
      link="base_link" />
    <child
      link="imu_targetpoint0" />
    <axis
      xyz="0 0 0" />
  </joint>
  <link
    name="imu_naviguider0">
    <inertial>
      <origin
        xyz="-0.0322597491033754 -0.0230937369873633 0.0513063887266468"
        rpy="0 0 0" />
      <mass
        value="0.00104001214902657" />
      <inertia
        ixx="4.5402102971104E-08"
        ixy="-1.1379573336823E-12"
        ixz="6.59636597834267E-13"
        iyy="2.41782094463895E-08"
        iyz="-1.49034263152175E-11"
        izz="6.85120415669947E-08" />
    </inertial>
    <visual>
      <origin
        xyz="0 0 0"
        rpy="0 0 0" />
      <geometry>
        <mesh
          filename="package://urdf_export_5/meshes/imu_naviguider0.STL" />
      </geometry>
      <material
        name="">
        <color
          rgba="0.792156862745098 0.819607843137255 0.933333333333333 1" />
      </material>
    </visual>
    <collision>
      <origin
        xyz="0 0 0"
        rpy="0 0 0" />
      <geometry>
        <mesh
          filename="package://urdf_export_5/meshes/imu_naviguider0.STL" />
      </geometry>
    </collision>
  </link>
  <joint
    name="imu_naviguider0_joint"
    type="fixed">
    <origin
      xyz="0 0 0"
      rpy="0 0 0" />
    <parent
      link="base_link" />
    <child
      link="imu_naviguider0" />
    <axis
      xyz="0 0 0" />
  </joint>
  <link
    name="imu_naviguider1">
    <inertial>
      <origin
        xyz="0.0327400348966246 0.0219060630126367 0.0513063887266468"
        rpy="0 0 0" />
      <mass
        value="0.00104001214902657" />
      <inertia
        ixx="4.5402102971104E-08"
        ixy="-1.13795733367455E-12"
        ixz="6.59636597834305E-13"
        iyy="2.41782094463895E-08"
        iyz="-1.49034263152178E-11"
        izz="6.85120415669947E-08" />
    </inertial>
    <visual>
      <origin
        xyz="0 0 0"
        rpy="0 0 0" />
      <geometry>
        <mesh
          filename="package://urdf_export_5/meshes/imu_naviguider1.STL" />
      </geometry>
      <material
        name="">
        <color
          rgba="0.792156862745098 0.819607843137255 0.933333333333333 1" />
      </material>
    </visual>
    <collision>
      <origin
        xyz="0 0 0"
        rpy="0 0 0" />
      <geometry>
        <mesh
          filename="package://urdf_export_5/meshes/imu_naviguider1.STL" />
      </geometry>
    </collision>
  </link>
  <joint
    name="imu_naviguider1_joint"
    type="fixed">
    <origin
      xyz="0 0 0"
      rpy="0 0 0" />
    <parent
      link="base_link" />
    <child
      link="imu_naviguider1" />
    <axis
      xyz="0 0 0" />
  </joint>
  <link
    name="imu_targetpoint1">
    <inertial>
      <origin
        xyz="-0.025463611961184 0.0204537468318315 0.0463231699704986"
        rpy="0 0 0" />
      <mass
        value="0.00550725674074067" />
      <inertia
        ixx="5.70520825882088E-07"
        ixy="-9.49293716940134E-09"
        ixz="-5.68176309907189E-10"
        iyy="6.25529402959274E-07"
        iyz="4.94930664045408E-10"
        izz="1.15056899729882E-06" />
    </inertial>
    <visual>
      <origin
        xyz="0 0 0"
        rpy="0 0 0" />
      <geometry>
        <mesh
          filename="package://urdf_export_5/meshes/imu_targetpoint1.STL" />
      </geometry>
      <material
        name="">
        <color
          rgba="0.792156862745098 0.819607843137255 0.933333333333333 1" />
      </material>
    </visual>
    <collision>
      <origin
        xyz="0 0 0"
        rpy="0 0 0" />
      <geometry>
        <mesh
          filename="package://urdf_export_5/meshes/imu_targetpoint1.STL" />
      </geometry>
    </collision>
  </link>
  <joint
    name="imu_targetpoint1_joint"
    type="fixed">
    <origin
      xyz="0 0 0"
      rpy="0 0 0" />
    <parent
      link="base_link" />
    <child
      link="imu_targetpoint1" />
    <axis
      xyz="0 0 0" />
  </joint>
</robot>